<?xml version="1.0"?>
<robot name="robot">
    
	<link name="base_link">
    </link>

    <link name="camera_link_optical">
    </link>

    <link name="body">
        <visual>
            <geometry>
                <box size="0.4 0.5 0.1"/>
            </geometry>
        </visual>
        <collision>
            <geometry>
                <box size="0.4 0.3 0.2"/>
            </geometry>
        </collision>
        <inertial>
            <origin xyz="0 0 0" rpy="0 0 0"/>
            <mass value="1.0"/>
            <inertia
                ixx="0.2" ixy="0.0" ixz="0.0"
                iyy="0.3" iyz="0.0"
                izz="0.5"/>
        </inertial>
    </link>


    <link name="camera_link">
        <visual>
            <geometry>
                <box size="0.02 0.1 0.02"/>
            </geometry>
        </visual>
        <collision>
            <geometry>
                <box size="0.1 0.02 0.02"/>
            </geometry>
        </collision>
        <inertial>
            <origin xyz="0 0 0" rpy="0 0 0"/>
            <mass value="0.01"/>
            <inertia
                ixx="0.001" ixy="0.0" ixz="0.0"
                iyy="0.001" iyz="0.0"
                izz="0.001"/>
        </inertial>
    </link>
    
    <link name="front_left">
        <visual>
            <geometry>
                <cylinder length="0.05" radius="0.1"/>
            </geometry>
        </visual>
        <collision>
            <geometry>
                <cylinder length="0.05" radius="0.1"/>
            </geometry>
        </collision>
        <inertial>
            <origin xyz="0 0 0" rpy="0 0 0"/>
            <mass value="0.5"/>
            <inertia
                ixx="0.1" ixy="0.0" ixz="0.0"
                iyy="0.1" iyz="0.0"
                izz="0.1"/>
        </inertial>
    </link>
    
    <link name="front_right">
        <visual>
            <geometry>
                <cylinder length="0.05" radius="0.1"/>
            </geometry>
        </visual>
        <collision>
            <geometry>
                <cylinder length="0.05" radius="0.1"/>
            </geometry>
        </collision>
        <inertial>
            <origin xyz="0 0 0" rpy="0 0 0"/>
            <mass value="0.5"/>
            <inertia
                ixx="0.1" ixy="0.0" ixz="0.0"
                iyy="0.1" iyz="0.0"
                izz="0.1"/>
        </inertial>
    </link>
    
    <link name="rear_left">
        <visual>
            <geometry>
                <cylinder length="0.05" radius="0.1"/>
            </geometry>
        </visual>
        <collision>
            <geometry>
                <cylinder length="0.05" radius="0.1"/>
            </geometry>
        </collision>
        <inertial>
            <origin xyz="0 0 0" rpy="0 0 0"/>
            <mass value="0.5"/>
            <inertia
                ixx="0.1" ixy="0.0" ixz="0.0"
                iyy="0.1" iyz="0.0"
                izz="0.1"/>
        </inertial>
    </link>

    <link name="rear_right">
        <visual>
            <geometry>
                <cylinder length="0.05" radius="0.1"/>
            </geometry>
        </visual>
        <collision>
            <geometry>
                <cylinder length="0.05" radius="0.1"/>
            </geometry>
        </collision>
        <inertial>
            <origin xyz="0 0 0" rpy="0 0 0"/>
            <mass value="0.5"/>
            <inertia
                ixx="0.1" ixy="0.0" ixz="0.0"
                iyy="0.1" iyz="0.0"
                izz="0.1"/>
        </inertial>
    </link>


    <joint name="chassis_joint" type="fixed">
        <parent link="base_link"/>
        <child link="body"/>
    </joint>
    
    <joint name="front_left_joint" type="continuous">
        <parent link="body"/>
        <child link="front_left"/>
        <origin xyz="0.2 0.275 -0.2" rpy="-1.5707 0 0"/>
        <axis xyz="0 0 1"/>
    </joint>

    <joint name="front_right_joint" type="continuous">
        <parent link="body"/>
        <child link="front_right"/>
        <origin xyz="0.2 -0.275 -0.2" rpy="1.5707 0 0"/>
        <axis xyz="0 0 -1"/>
    </joint>

    <joint name="rear_left_joint" type="continuous">
        <parent link="body"/>
        <child link="rear_left"/>
        <origin xyz="-0.2 0.275 -0.2" rpy="-1.5707 0 0"/>
        <axis xyz="0 0 1"/>
    </joint>

    <joint name="rear_right_joint" type="continuous">
        <parent link="body"/>
        <child link="rear_right"/>
        <origin xyz="-0.2 -0.275 -0.2" rpy="1.5707 0 0"/>
        <axis xyz="0 0 -1"/>
    </joint>
    
    <joint name="camera_joint" type="fixed">
        <parent link="body"/>
        <child link="camera_link"/>
        <origin xyz="0 0 0.5" rpy="0 0 0"/>
        <axis xyz="0 1 0"/>
    </joint>

    <joint name="camera_optical_joint" type="fixed">
        <!-- keep these params the same or gazebo does weird things -->
        <origin xyz="0 0 0" rpy="-1.57 0 1.57"/>
        <parent link="camera_link"/>
        <child link="camera_link_optical"/>
    </joint>

    <transmission name="front_left_tran">
        <type>transmission_interface/SimpleTransmission</type>
        <joint name="front_left_joint">
            <hardwareInterface>hardware_interface/EffortJointInterface</hardwareInterface>
        </joint>
        <actuator name="front_left_motor">
            <hardwareInterface>hardware_interface/EffortJointInterface</hardwareInterface>
            <mechanicalReduction>1</mechanicalReduction>
        </actuator>
    </transmission>

    <transmission name="front_right_tran">
        <type>transmission_interface/SimpleTransmission</type>
        <joint name="front_right_joint">
            <hardwareInterface>hardware_interface/EffortJointInterface</hardwareInterface>
        </joint>
        <actuator name="front_right_motor">
            <hardwareInterface>hardware_interface/EffortJointInterface</hardwareInterface>
            <mechanicalReduction>1</mechanicalReduction>
        </actuator>
    </transmission>

    <transmission name="rear_left_tran">
        <type>transmission_interface/SimpleTransmission</type>
        <joint name="rear_left_joint">
            <hardwareInterface>hardware_interface/EffortJointInterface</hardwareInterface>
        </joint>
        <actuator name="rear_left_motor">
            <hardwareInterface>hardware_interface/EffortJointInterface</hardwareInterface>
            <mechanicalReduction>1</mechanicalReduction>
        </actuator>
    </transmission>

    <transmission name="rear_right_tran">
        <type>transmission_interface/SimpleTransmission</type>
        <joint name="rear_right_joint">
            <hardwareInterface>hardware_interface/EffortJointInterface</hardwareInterface>
        </joint>
        <actuator name="rear_right_motor">
            <hardwareInterface>hardware_interface/EffortJointInterface</hardwareInterface>
            <mechanicalReduction>1</mechanicalReduction>
        </actuator>
    </transmission>

    <gazebo reference="front_left">
        <mu1>0.2</mu1>
        <mu2>0.2</mu2>
    </gazebo>
    
    <gazebo reference="front_right">
        <mu1>0.2</mu1>
        <mu2>0.2</mu2>
    </gazebo>

    <gazebo reference="rear_left">
        <mu1>0.2</mu1>
        <mu2>0.2</mu2>
    </gazebo>
    
    <gazebo reference="rear_right">
        <mu1>0.2</mu1>
        <mu2>0.2</mu2>
    </gazebo>

    <!-- camera -->
    <gazebo reference="camera_link">
        <sensor type="camera" name="camera1">
            <update_rate>30.0</update_rate>
            <camera name="head">
                <horizontal_fov>1.3962634</horizontal_fov>
                <image>
                    <width>800</width>
                    <height>800</height>
                    <format>R8G8B8</format>
                </image>
                <clip>
                    <near>0.02</near>
                    <far>300</far>
                </clip>
                <noise>
                    <type>gaussian</type>
                    <!-- Noise is sampled independently per pixel on each frame.
                        That pixel's noise value is added to each of its color
                        channels, which at that point lie in the range [0,1]. -->
                    <mean>0.0</mean>
                    <stddev>0.007</stddev>
                </noise>
            </camera>
            <plugin name="camera_controller" filename="libgazebo_ros_camera.so">
                <alwaysOn>true</alwaysOn>
                <updateRate>0.0</updateRate>
                <cameraName>robot/camera1</cameraName>
                <imageTopicName>image_raw</imageTopicName>
                <cameraInfoTopicName>camera_info</cameraInfoTopicName>
                <frameName>camera_link_optical</frameName>
                <!-- setting hackBaseline to anything but 0.0 will cause a misalignment
                    between the gazebo sensor image and the frame it is supposed to
                    be attached to -->
                <hackBaseline>0.0</hackBaseline>
                <distortionK1>0.0</distortionK1>
                <distortionK2>0.0</distortionK2>
                <distortionK3>0.0</distortionK3>
                <distortionT1>0.0</distortionT1>
                <distortionT2>0.0</distortionT2>
                <CxPrime>0</CxPrime>
                <Cx>0.0</Cx>
                <Cy>0.0</Cy>
                <focalLength>0.0</focalLength>
            </plugin>
        </sensor>
    </gazebo>

    <gazebo>
        <plugin name="gazebo_ros_control" filename="libgazebo_ros_control.so">
            <robotNamespace>/robot</robotNamespace>
            <robotSimType>gazebo_ros_control/DefaultRobotHWSim</robotSimType>
        </plugin>
    </gazebo>

</robot>
